19:22:42 07/04/2020 - 312Traceback (most recent call last):
  File "/Users/jocker/astwobytes/env/lib/python3.6/site-packages/django/core/management/__init__.py", line 102, in call_command
    app_name = get_commands()[command_name]
KeyError: '312'

During handling of the above exception, another exception occurred:

Traceback (most recent call last):
  File "/Users/jocker/astwobytes/apps/main_functions/management/commands/tasks.py", line 53, in run_task
    call_command(command, **opts)
  File "/Users/jocker/astwobytes/env/lib/python3.6/site-packages/django/core/management/__init__.py", line 104, in call_command
    raise CommandError("Unknown command: %r" % command_name)
django.core.management.base.CommandError: Unknown command: '312'

19:22:42 07/04/2020 - 321Traceback (most recent call last):
  File "/Users/jocker/astwobytes/env/lib/python3.6/site-packages/django/core/management/__init__.py", line 102, in call_command
    app_name = get_commands()[command_name]
KeyError: '321'

During handling of the above exception, another exception occurred:

Traceback (most recent call last):
  File "/Users/jocker/astwobytes/apps/main_functions/management/commands/tasks.py", line 53, in run_task
    call_command(command, **opts)
  File "/Users/jocker/astwobytes/env/lib/python3.6/site-packages/django/core/management/__init__.py", line 104, in call_command
    raise CommandError("Unknown command: %r" % command_name)
django.core.management.base.CommandError: Unknown command: '321'

